Workbook

Sheet Cover
B2: Halcyon Packaging Co.
B3: Leveraged buyout model
B4: Fictional company. Illustrative figures only; not investment advice.
B5: Built by Adham Karim (github.com/adhamkarim4815/lbo-lab)
B7: Active case | C7: =Inputs!$D$5 -> Base
B8: Model status | C8: =Checks!$F$26 -> ALL CHECKS PASS
B9: Sponsor IRR / MOIC | C9: =TEXT(Returns!$D$33,"0.0%")&" / "&TEXT(Returns!$D$32,"0.00")&"x" -> 16.5% / 2.15x
B11: Sheet | C11: Purpose
B12: Summary | C12: One-page returns summary: S&U, bridge, credit statistics and charts.
B13: Inputs | C13: Every hard-coded assumption, the scenario dropdown (cell D5) and the three operating cases.
B14: Transaction | C14: Purchase price, fees, sources and uses, capitalization and ownership.
B15: Operating | C15: Revenue to EBITDA, taxes, free cash flow before and after debt service.
B16: Debt | C16: Cash waterfall, revolver, term loan (amortization + sweep), PIK-able notes, credit statistics.
B17: Returns | C17: Exit valuation, sponsor IRR and MOIC, option pool, value creation bridge.
B18: Sensitivity | C18: Live-formula IRR and MOIC grids: entry vs exit multiple, exit multiple vs exit year.
B19: Checks | C19: Integrity checks: sources = uses, balances, roll-forwards, bridge, grid reconciliation.
B21: Colour code
B22: 1,234.5 | C22: Blue on cream: hard-coded input. Change these (Inputs sheet only).
B23: 1,234.5 | C23: Black: formula or calculation on the same sheet.
B24: 1,234.5 | C24: Green: direct link to another sheet.
B26: Conventions
B27: 1. | C27: USD millions unless stated. Year 0 is the closing balance sheet (LTM period); years 1 to 7 are projections.
B28: 2. | C28: Interest accrues on opening balances, so there are no circular references and no iterative calculation.
B29: 3. | C29: Cash waterfall: free cash flow after mandatory amortization, then revolver draw or repayment, then the cash sweep.
B30: 4. | C30: Sweep = sweep % x excess cash flow (period cash flow after mandatory amortization and revolver repayment).
B31: 5. | C31: Bridge: EBITDA growth at the entry multiple; multiple expansion on exit EBITDA; net debt paydown; fees. Parts sum exactly.
B32: 6. | C32: Switch case with the dropdown in Inputs!D5. The Python engine (lbo run) reproduces every number here.
B33: 7. | C33: Halcyon Packaging Co. is fictional. Fees and taxes are simplified; see the repository README for limitations.

Sheet Summary
B1: =Inputs!$D$12&" | LBO returns summary | "&Inputs!$D$5&" case" -> Halcyon Packaging Co. | LBO returns summary | Base case
B2: USD millions. Fictional company, illustrative only. All figures link to the model sheets.
B4: Transaction | F4: Returns
B5: Enterprise value | D5: =Transaction!$D$7 -> 900 | F5: Exit year | K5: =Returns!$D$5 -> 5
B6: Entry EV / LTM EBITDA | D6: =Transaction!$D$6 -> 9 | F6: Exit EV / EBITDA | K6: =Returns!$D$6 -> 9
B7: Total debt / LTM EBITDA at close | D7: =Transaction!$F$41 -> 5.5 | F7: Exit enterprise value | K7: =Returns!$D$17 -> 1256.1972
B8: Sponsor equity | D8: =Transaction!$D$22 -> 378.25 | F8: Exit equity value (100%) | K8: =Returns!$D$23 -> 891.26181
B9: Total equity % of capitalization | D9: =Transaction!$E$44 -> 0.42302649 | F9: Sponsor proceeds | K9: =Returns!$D$30 -> 813.11905
B10: Fees (transaction + financing) | D10: =Transaction!$D$9+Transaction!$D$13 -> 33.25 | F10: Sponsor MOIC | K10: =Returns!$D$32 -> 2.1496869
B11: Model checks | D11: =Checks!$F$26 -> ALL CHECKS PASS | F11: Sponsor IRR | K11: =Returns!$D$33 -> 0.16540007
B13: Sources and uses | F13: Value creation bridge (100% of equity)
B14: Revolver | D14: =Transaction!$D$18 -> 0 | E14: =Transaction!$D$18/Transaction!$D$23 -> 0 | F14: Entry equity | J14: =Returns!$D$37 -> 403.25
B15: Senior term loan | D15: =Transaction!$D$19 -> 400 | E15: =Transaction!$D$19/Transaction!$D$23 -> 0.4196171 | F15: EBITDA growth | J15: =Returns!$D$38 -> 356.19722 | K15: =Returns!$E$38 -> 0.72989467
B16: Subordinated notes | D16: =Transaction!$D$20 -> 150 | E16: =Transaction!$D$20/Transaction!$D$23 -> 0.15735641 | F16: Multiple expansion | J16: =Returns!$D$39 -> 0 | K16: =Returns!$E$39 -> 0
B17: Management rollover | D17: =Transaction!$D$21 -> 25 | E17: =Transaction!$D$21/Transaction!$D$23 -> 0.026226069 | F17: Net debt paydown | J17: =Returns!$D$40 -> 165.06459 | K17: =Returns!$E$40 -> 0.33823892
B18: Sponsor equity | D18: =Transaction!$D$22 -> 378.25 | E18: =Transaction!$D$22/Transaction!$D$23 -> 0.39680042 | F18: Transaction costs | J18: =Returns!$D$41 -> -33.25 | K18: =Returns!$E$41 -> -0.068133597
B19: Total sources | D19: =Transaction!$D$23 -> 953.25 | E19: =Transaction!$D$23/Transaction!$D$23 -> 1 | F19: Exit equity value | J19: =Returns!$D$43 -> 891.26181
B20: Enterprise value | D20: =Transaction!$D$27 -> 900 | E20: =Transaction!$D$27/Transaction!$D$31 -> 0.94413847 | F20: Less: option pool | J20: =Returns!$D$45 -> -24.400591
B21: Fees and expenses | D21: =Transaction!$D$28+Transaction!$D$29 -> 33.25 | E21: =(Transaction!$D$28+Transaction!$D$29)/Transaction!$D$31 -> 0.034880671 | F21: Sponsor equity gain | J21: =Returns!$D$48 -> 434.86905
B22: Minimum cash | D22: =Transaction!$D$30 -> 20 | E22: =Transaction!$D$30/Transaction!$D$31 -> 0.020980855 | F22: Sponsor MOIC / IRR | J22: =Returns!$D$32 -> 2.1496869 | K22: =Returns!$D$33 -> 0.16540007
B23: Total uses | D23: =Transaction!$D$31 -> 953.25 | E23: =Transaction!$D$31/Transaction!$D$31 -> 1
B25: Projections and credit statistics | D25: =Debt!D6 -> Close | E25: =Debt!E6 -> FY2027E | F25: =Debt!F6 -> FY2028E | G25: =Debt!G6 -> FY2029E | H25: =Debt!H6 -> FY2030E | I25: =Debt!I6 -> FY2031E | J25: =Debt!J6 -> FY2032E | K25: =Debt!K6 -> FY2033E
B26: Revenue | D26: =Operating!D18 -> 625 | E26: =Operating!E18 -> 662.5 | F26: =Operating!F18 -> 698.9375 | G26: =Operating!G18 -> 733.88437 | H26: =Operating!H18 -> 766.90917 | I26: =Operating!I18 -> 797.58554 | J26: =Operating!J18 -> 829.48896 | K26: =Operating!K18 -> 858.52107
B27: EBITDA | D27: =Operating!D20 -> 100 | E27: =Operating!E20 -> 106 | F27: =Operating!F20 -> 114.62575 | G27: =Operating!G20 -> 123.29257 | H27: =Operating!H20 -> 131.90838 | I27: =Operating!I20 -> 139.57747 | J27: =Operating!J20 -> 147.64903 | K27: =Operating!K20 -> 154.53379
B28: EBITDA margin | D28: =Operating!D19 -> 0.16 | E28: =Operating!E19 -> 0.16 | F28: =Operating!F19 -> 0.164 | G28: =Operating!G19 -> 0.168 | H28: =Operating!H19 -> 0.172 | I28: =Operating!I19 -> 0.175 | J28: =Operating!J19 -> 0.178 | K28: =Operating!K19 -> 0.18
B29: FCF before debt service | E29: =Operating!E40 -> 70.175893 | F29: =Operating!F40 -> 75.396975 | G29: =Operating!G40 -> 80.622653 | H29: =Operating!H40 -> 85.787663 | I29: =Operating!I40 -> 90.22345 | J29: =Operating!J40 -> 94.366703 | K29: =Operating!K40 -> 98.054899
B30: FCF after debt service | E30: =Operating!E44 -> 8.7758929 | F30: =Operating!F44 -> 15.491772 | G30: =Operating!G44 -> 22.686557 | H30: =Operating!H44 -> 30.328805 | I30: =Operating!I44 -> 37.781564 | J30: =Operating!J44 -> 45.46814 | K30: =Operating!K44 -> 53.242523
B31: Total debt | D31: =Debt!D61 -> 550 | E31: =Debt!E61 -> 533.41808 | F31: =Debt!F61 -> 511.79925 | G31: =Debt!G61 -> 484.78433 | H31: =Debt!H61 -> 452.03773 | I31: =Debt!I61 -> 413.70156 | J31: =Debt!J61 -> 369.60045 | K31: =Debt!K61 -> 319.66856
B32: Net debt | D32: =Debt!D64 -> 530 | E32: =Debt!E64 -> 511.22411 | F32: =Debt!F64 -> 485.73233 | G32: =Debt!G64 -> 453.04578 | H32: =Debt!H64 -> 412.71697 | I32: =Debt!I64 -> 364.93541 | J32: =Debt!J64 -> 309.46727 | K32: =Debt!K64 -> 246.22475
B33: Total debt / EBITDA | D33: =Debt!D70 -> 5.5 | E33: =Debt!E70 -> 5.032246 | F33: =Debt!F70 -> 4.4649588 | G33: =Debt!G70 -> 3.9319832 | H33: =Debt!H70 -> 3.4269069 | I33: =Debt!I70 -> 2.9639566 | J33: =Debt!J70 -> 2.5032365 | K33: =Debt!K70 -> 2.0685997
B34: Senior debt / EBITDA | D34: =Debt!D71 -> 4 | E34: =Debt!E71 -> 3.6171517 | F34: =Debt!F71 -> 3.1563523 | G34: =Debt!G71 -> 2.7153649 | H34: =Debt!H71 -> 2.289754 | I34: =Debt!I71 -> 1.8892846 | J34: =Debt!J71 -> 1.4873138 | K34: =Debt!K71 -> 1.0979382
B35: Interest coverage (EBITDA / cash interest) | E35: =Debt!E73 -> 2.046332 | F35: =Debt!F73 -> 2.2766205 | G35: =Debt!G73 -> 2.544348 | H35: =Debt!H73 -> 2.8617486 | I35: =Debt!I73 -> 3.2288446 | J35: =Debt!J73 -> 3.7029005 | K35: =Debt!K73 -> 4.2908128
B36: Fixed charge coverage | E36: =Debt!E75 -> 1.2083478 | F36: =Debt!F75 -> 1.321801 | G36: =Debt!G75 -> 1.4509066 | H36: =Debt!H75 -> 1.6000148 | I36: =Debt!I75 -> 1.7641858 | J36: =Debt!J75 -> 1.9688683 | K36: =Debt!K75 -> 2.2066427
F54: Financing summary | H54: $mm | I54: x EBITDA | J54: Rate | K54: Amort.
F55: Revolver (commitment) | H55: =Inputs!$D$25 -> 60 | J55: =Transaction!$G$18 -> 0.08
F56: Senior term loan | H56: =Transaction!$D$19 -> 400 | I56: =Transaction!$F$19 -> 4 | J56: =Transaction!$G$19 -> 0.0875 | K56: =Inputs!$E$39 -> 0.025
F57: Subordinated notes | H57: =Transaction!$D$20 -> 150 | I57: =Transaction!$F$20 -> 1.5 | J57: =Transaction!$G$20 -> 0.11
F58: Cash sweep (% of excess cash flow) | K58: =Inputs!$D$37 -> 0.75
F59: Sub notes pay in kind (1 = yes) | K59: =Inputs!$D$35 -> 0
F60: Minimum cash | K60: =Inputs!$D$20 -> 20
...

Sheet Inputs
B1: Halcyon Packaging Co. | Inputs
B2: USD millions unless stated. Blue cells on a cream fill are hard-coded inputs; everything else in the workbook is a formula.
B4: Scenario selector
B5: Active case (choose from dropdown) | D5: Base
B6: Case index | D6: =MATCH(D5,D7:D9,0) -> 1
B7: Case 1 name | D7: Base
B8: Case 2 name | D8: Management
B9: Case 3 name | D9: Downside
B11: Transaction
B12: Target company (fictional) | D12: Halcyon Packaging Co.
B13: Closing fiscal year (LTM period) | C13: year | D13: 2026
B14: LTM revenue | C14: $mm | D14: 625
B15: LTM EBITDA | C15: $mm | D15: 100
B16: Entry EV / LTM EBITDA | C16: x | D16: 9
B17: Transaction fees | C17: % of EV | D17: 0.02
B18: Financing fees | C18: % of committed debt | D18: 0.025
B19: Financing fee amortization period | C19: years | D19: 7
B20: Minimum cash (funded at close) | C20: $mm | D20: 20
B21: Management rollover equity | C21: $mm | D21: 25
B22: Management option pool | C22: % of equity gain | D22: 0.05
B24: Financing
B25: Revolver commitment | C25: $mm | D25: 60
B26: Revolver drawn at close | C26: $mm | D26: 0
B27: Senior term loan | C27: x LTM EBITDA | D27: 4
B28: Subordinated notes | C28: x LTM EBITDA | D28: 1.5
B29: Base rate | C29: % | D29: 0.04
B30: Revolver spread | C30: % | D30: 0.04
B31: Term loan spread | C31: % | D31: 0.0475
B32: Revolver commitment fee (undrawn) | C32: % | D32: 0.005
B33: Sub notes coupon, cash pay | C33: % | D33: 0.11
B34: Sub notes coupon, if PIK | C34: % | D34: 0.12
B35: Sub notes PIK toggle (1 = PIK, 0 = cash) | C35: switch | D35: 0
B36: Interest income on cash | C36: % | D36: 0.02
B37: Cash sweep | C37: % of excess cash flow | D37: 0.75
B38: Projection year | E38: =COLUMN()-COLUMN($D$1) -> 1 | F38: =COLUMN()-COLUMN($D$1) -> 2 | G38: =COLUMN()-COLUMN($D$1) -> 3 | H38: =COLUMN()-COLUMN($D$1) -> 4 | I38: =COLUMN()-COLUMN($D$1) -> 5 | J38: =COLUMN()-COLUMN($D$1) -> 6 | K38: =COLUMN()-COLUMN($D$1) -> 7
B39: Term loan mandatory amortization | C39: % of original | E39: 0.025 | F39: 0.025 | G39: 0.025 | H39: 0.025 | I39: 0.025 | J39: 0.025 | K39: 0.025
B41: Operating (all cases)
B42: D&A | C42: % of revenue | D42: 0.03
B43: Net working capital investment | C43: % of revenue change | D43: 0.12
B44: Cash tax rate | C44: % of EBT | D44: 0.25
...

Sheet Transaction
B1: Transaction | purchase price, sources and uses, capitalization
B2: USD millions. Fees are paid at close; financing fees are capitalized and amortized.
B4: Purchase price and fees
B5: LTM EBITDA | D5: =Inputs!$D$15 -> 100
B6: Entry EV / LTM EBITDA | D6: =Inputs!$D$16 -> 9
B7: Enterprise value | D7: =D5*D6 -> 900
B8: Transaction fees (% of EV) | D8: =Inputs!$D$17 -> 0.02
B9: Transaction fees | D9: =D7*D8 -> 18
B10: Financing fees (% of committed debt) | D10: =Inputs!$D$18 -> 0.025
B11: Revolver commitment | D11: =Inputs!$D$25 -> 60
B12: Committed debt (revolver + term loan + notes) | D12: =D11+D19+D20 -> 610
B13: Financing fees | D13: =D12*D10 -> 15.25
B14: Minimum cash funded at close | D14: =Inputs!$D$20 -> 20
B16: Sources of funds
B17: Sources | D17: $mm | E17: % of total | F17: x LTM EBITDA | G17: Rate
B18: Revolver (drawn at close) | D18: =Inputs!$D$26 -> 0 | E18: =D18/$D$23 -> 0 | F18: =D18/D5 -> 0 | G18: =Debt!$D$11 -> 0.08
B19: Senior term loan | D19: =Inputs!$D$27*D5 -> 400 | E19: =D19/$D$23 -> 0.4196171 | F19: =D19/D5 -> 4 | G19: =Debt!$D$13 -> 0.0875
B20: Subordinated notes | D20: =Inputs!$D$28*D5 -> 150 | E20: =D20/$D$23 -> 0.15735641 | F20: =D20/D5 -> 1.5 | G20: =Debt!$D$14 -> 0.11
B21: Management rollover equity | D21: =Inputs!$D$21 -> 25 | E21: =D21/$D$23 -> 0.026226069 | F21: =D21/D5 -> 0.25
B22: Sponsor equity (plug) | D22: =D31-D18-D19-D20-D21 -> 378.25 | E22: =D22/$D$23 -> 0.39680042 | F22: =D22/D5 -> 3.7825
B23: Total sources | D23: =SUM(D18:D22) -> 953.25 | E23: =D23/$D$23 -> 1 | F23: =D23/D5 -> 9.5325
B25: Uses of funds
B26: Uses | D26: $mm | E26: % of total | F26: x LTM EBITDA
B27: Purchase of enterprise value | D27: =D7 -> 900 | E27: =D27/$D$31 -> 0.94413847 | F27: =D27/D5 -> 9
B28: Transaction fees | D28: =D9 -> 18 | E28: =D28/$D$31 -> 0.018882769 | F28: =D28/D5 -> 0.18
B29: Financing fees | D29: =D13 -> 15.25 | E29: =D29/$D$31 -> 0.015997902 | F29: =D29/D5 -> 0.1525
B30: Minimum cash to balance sheet | D30: =D14 -> 20 | E30: =D30/$D$31 -> 0.020980855 | F30: =D30/D5 -> 0.2
B31: Total uses | D31: =SUM(D27:D30) -> 953.25 | E31: =D31/$D$31 -> 1 | F31: =D31/D5 -> 9.5325
B33: Check: total sources less total uses | D33: =D23-D31 -> 0
B35: Capitalization at close
B36: Tranche | D36: $mm | E36: % of total cap | F36: x LTM EBITDA
B37: Revolver | D37: =D18 -> 0 | E37: =D37/$D$45 -> 0 | F37: =D37/D5 -> 0
B38: Senior term loan | D38: =D19 -> 400 | E38: =D38/$D$45 -> 0.4196171 | F38: =D38/D5 -> 4
B39: Total senior debt | D39: =D37+D38 -> 400 | E39: =D39/$D$45 -> 0.4196171 | F39: =D39/D5 -> 4
B40: Subordinated notes | D40: =D20 -> 150 | E40: =D40/$D$45 -> 0.15735641 | F40: =D40/D5 -> 1.5
B41: Total debt | D41: =D39+D40 -> 550 | E41: =D41/$D$45 -> 0.57697351 | F41: =D41/D5 -> 5.5
B42: Less: cash | D42: =D30 -> 20 | F42: =D42/D5 -> 0.2
B43: Net debt | D43: =D41-D42 -> 530 | F43: =D43/D5 -> 5.3
B44: Total equity (sponsor + rollover) | D44: =D22+D21 -> 403.25 | E44: =D44/$D$45 -> 0.42302649 | F44: =D44/D5 -> 4.0325
B45: Total capitalization (debt + equity) | D45: =D41+D44 -> 953.25 | E45: =D45/$D$45 -> 1 | F45: =D45/D5 -> 9.5325
...

Sheet Operating
B1: Operating projections and free cash flow
B2: USD millions. Costs are shown as positive numbers and subtracted. Taxes are computed after interest.
B4: Projection year | D4: =COLUMN()-COLUMN($D$1) -> 0 | E4: =COLUMN()-COLUMN($D$1) -> 1 | F4: =COLUMN()-COLUMN($D$1) -> 2 | G4: =COLUMN()-COLUMN($D$1) -> 3 | H4: =COLUMN()-COLUMN($D$1) -> 4 | I4: =COLUMN()-COLUMN($D$1) -> 5 | J4: =COLUMN()-COLUMN($D$1) -> 6 | K4: =COLUMN()-COLUMN($D$1) -> 7
B5: Fiscal year | D5: =$D$8+D4 -> 2026 | E5: =$D$8+E4 -> 2027 | F5: =$D$8+F4 -> 2028 | G5: =$D$8+G4 -> 2029 | H5: =$D$8+H4 -> 2030 | I5: =$D$8+I4 -> 2031 | J5: =$D$8+J4 -> 2032 | K5: =$D$8+K4 -> 2033
B7: Linked assumptions
B8: Closing fiscal year | D8: =Inputs!$D$13 -> 2026
B9: D&A (% of revenue) | D9: =Inputs!$D$42 -> 0.03
B10: NWC investment (% of revenue change) | D10: =Inputs!$D$43 -> 0.12
B11: Cash tax rate | D11: =Inputs!$D$44 -> 0.25
B12: Capex (% of revenue, selected case) | D12: =Inputs!$D$74 -> 0.035
B13: Financing fee amortization (years) | D13: =Inputs!$D$19 -> 7
B14: Capitalized financing fees | D14: =Transaction!$D$13 -> 15.25
B16: Operating build
B17: Revenue growth | C17: % | E17: =Inputs!$E$72 -> 0.06 | F17: =Inputs!$F$72 -> 0.055 | G17: =Inputs!$G$72 -> 0.05 | H17: =Inputs!$H$72 -> 0.045 | I17: =Inputs!$I$72 -> 0.04 | J17: =Inputs!$J$72 -> 0.04 | K17: =Inputs!$K$72 -> 0.035
B18: Revenue | C18: $mm | D18: =Inputs!$D$14 -> 625 | E18: =D18*(1+E17) -> 662.5 | F18: =E18*(1+F17) -> 698.9375 | G18: =F18*(1+G17) -> 733.88437 | H18: =G18*(1+H17) -> 766.90917 | I18: =H18*(1+I17) -> 797.58554 | J18: =I18*(1+J17) -> 829.48896 | K18: =J18*(1+K17) -> 858.52107
B19: EBITDA margin | C19: % | D19: =D20/D18 -> 0.16 | E19: =Inputs!$E$73 -> 0.16 | F19: =Inputs!$F$73 -> 0.164 | G19: =Inputs!$G$73 -> 0.168 | H19: =Inputs!$H$73 -> 0.172 | I19: =Inputs!$I$73 -> 0.175 | J19: =Inputs!$J$73 -> 0.178 | K19: =Inputs!$K$73 -> 0.18
B20: EBITDA | C20: $mm | D20: =Inputs!$D$15 -> 100 | E20: =E18*E19 -> 106 | F20: =F18*F19 -> 114.62575 | G20: =G18*G19 -> 123.29257 | H20: =H18*H19 -> 131.90838 | I20: =I18*I19 -> 139.57747 | J20: =J18*J19 -> 147.64903 | K20: =K18*K19 -> 154.53379
B21: Less: D&A | C21: $mm | E21: =$D$9*E18 -> 19.875 | F21: =$D$9*F18 -> 20.968125 | G21: =$D$9*G18 -> 22.016531 | H21: =$D$9*H18 -> 23.007275 | I21: =$D$9*I18 -> 23.927566 | J21: =$D$9*J18 -> 24.884669 | K21: =$D$9*K18 -> 25.755632
B22: EBIT | C22: $mm | E22: =E20-E21 -> 86.125 | F22: =F20-F21 -> 93.657625 | G22: =G20-G21 -> 101.27604 | H22: =H20-H21 -> 108.9011 | I22: =I20-I21 -> 115.6499 | J22: =J20-J21 -> 122.76437 | K22: =K20-K21 -> 128.77816
B23: Capex | C23: $mm | E23: =$D$12*E18 -> 23.1875 | F23: =$D$12*F18 -> 24.462812 | G23: =$D$12*G18 -> 25.685953 | H23: =$D$12*H18 -> 26.841821 | I23: =$D$12*I18 -> 27.915494 | J23: =$D$12*J18 -> 29.032114 | K23: =$D$12*K18 -> 30.048238
B24: Increase in net working capital | C24: $mm | E24: =$D$10*(E18-D18) -> 4.5 | F24: =$D$10*(F18-E18) -> 4.3725 | G24: =$D$10*(G18-F18) -> 4.193625 | H24: =$D$10*(H18-G18) -> 3.9629756 | I24: =$D$10*(I18-H18) -> 3.681164 | J24: =$D$10*(J18-I18) -> 3.8284106 | K24: =$D$10*(K18-J18) -> 3.4838536
B26: Taxes and net income
B27: EBIT | E27: =E22 -> 86.125 | F27: =F22 -> 93.657625 | G27: =G22 -> 101.27604 | H27: =H22 -> 108.9011 | I27: =I22 -> 115.6499 | J27: =J22 -> 122.76437 | K27: =K22 -> 128.77816
B28: Less: financing fee amortization | E28: =IF(E4<=$D$13,$D$14/$D$13,0) -> 2.1785714 | F28: =IF(F4<=$D$13,$D$14/$D$13,0) -> 2.1785714 | G28: =IF(G4<=$D$13,$D$14/$D$13,0) -> 2.1785714 | H28: =IF(H4<=$D$13,$D$14/$D$13,0) -> 2.1785714 | I28: =IF(I4<=$D$13,$D$14/$D$13,0) -> 2.1785714 | J28: =IF(J4<=$D$13,$D$14/$D$13,0) -> 2.1785714 | K28: =IF(K4<=$D$13,$D$14/$D$13,0) -> 2.1785714
B29: Less: total interest expense (cash + PIK) | E29: =Debt!E58 -> 51.8 | F29: =Debt!F58 -> 50.349082 | G29: =Debt!G58 -> 48.457434 | H29: =Debt!H58 -> 46.093629 | I29: =Debt!I58 -> 43.228301 | J29: =Debt!J58 -> 39.873886 | K29: =Debt!K58 -> 36.01504
B30: Plus: interest income | E30: =Debt!E56 -> 0.4 | F30: =Debt!F56 -> 0.44387946 | G30: =Debt!G56 -> 0.52133833 | H30: =Debt!H56 -> 0.63477111 | I30: =Debt!I56 -> 0.78641513 | J30: =Debt!J56 -> 0.97532295 | K30: =Debt!K56 -> 1.2026636
B31: Pre-tax income | E31: =E27-E28-E29+E30 -> 32.546429 | F31: =F27-F28-F29+F30 -> 41.573851 | G31: =G27-G28-G29+G30 -> 51.161376 | H31: =H27-H28-H29+H30 -> 61.263673 | I31: =I27-I28-I29+I30 -> 71.029445 | J31: =J27-J28-J29+J30 -> 81.687231 | K31: =K27-K28-K29+K30 -> 91.787214
B32: Less: cash taxes | E32: =MAX(0,E31)*$D$11 -> 8.1366071 | F32: =MAX(0,F31)*$D$11 -> 10.393463 | G32: =MAX(0,G31)*$D$11 -> 12.790344 | H32: =MAX(0,H31)*$D$11 -> 15.315918 | I32: =MAX(0,I31)*$D$11 -> 17.757361 | J32: =MAX(0,J31)*$D$11 -> 20.421808 | K32: =MAX(0,K31)*$D$11 -> 22.946803
B33: Net income | E33: =E31-E32 -> 24.409821 | F33: =F31-F32 -> 31.180388 | G33: =G31-G32 -> 38.371032 | H33: =H31-H32 -> 45.947755 | I33: =I31-I32 -> 53.272084 | J33: =J31-J32 -> 61.265424 | K33: =K31-K32 -> 68.84041
B35: Free cash flow
B36: EBITDA | E36: =E20 -> 106 | F36: =F20 -> 114.62575 | G36: =G20 -> 123.29257 | H36: =H20 -> 131.90838 | I36: =I20 -> 139.57747 | J36: =J20 -> 147.64903 | K36: =K20 -> 154.53379
B37: Less: cash taxes | E37: =E32 -> 8.1366071 | F37: =F32 -> 10.393463 | G37: =G32 -> 12.790344 | H37: =H32 -> 15.315918 | I37: =I32 -> 17.757361 | J37: =J32 -> 20.421808 | K37: =K32 -> 22.946803
B38: Less: capex | E38: =E23 -> 23.1875 | F38: =F23 -> 24.462812 | G38: =G23 -> 25.685953 | H38: =H23 -> 26.841821 | I38: =I23 -> 27.915494 | J38: =J23 -> 29.032114 | K38: =K23 -> 30.048238
B39: Less: increase in NWC | E39: =E24 -> 4.5 | F39: =F24 -> 4.3725 | G39: =G24 -> 4.193625 | H39: =H24 -> 3.9629756 | I39: =I24 -> 3.681164 | J39: =J24 -> 3.8284106 | K39: =K24 -> 3.4838536
B40: Free cash flow before debt service | E40: =E36-E37-E38-E39 -> 70.175893 | F40: =F36-F37-F38-F39 -> 75.396975 | G40: =G36-G37-G38-G39 -> 80.622653 | H40: =H36-H37-H38-H39 -> 85.787663 | I40: =I36-I37-I38-I39 -> 90.22345 | J40: =J36-J37-J38-J39 -> 94.366703 | K40: =K36-K37-K38-K39 -> 98.054899
B41: Less: net cash interest | E41: =Debt!E57 -> 51.4 | F41: =Debt!F57 -> 49.905203 | G41: =Debt!G57 -> 47.936096 | H41: =Debt!H57 -> 45.458858 | I41: =Debt!I57 -> 42.441886 | J41: =Debt!J57 -> 38.898563 | K41: =Debt!K57 -> 34.812376
B42: Free cash flow after interest | E42: =E40-E41 -> 18.775893 | F42: =F40-F41 -> 25.491772 | G42: =G40-G41 -> 32.686557 | H42: =H40-H41 -> 40.328805 | I42: =I40-I41 -> 47.781564 | J42: =J40-J41 -> 55.46814 | K42: =K40-K41 -> 63.242523
B43: Less: mandatory term loan amortization | E43: =Debt!E39 -> 10 | F43: =Debt!F39 -> 10 | G43: =Debt!G39 -> 10 | H43: =Debt!H39 -> 10 | I43: =Debt!I39 -> 10 | J43: =Debt!J39 -> 10 | K43: =Debt!K39 -> 10
B44: Free cash flow after debt service | E44: =E42-E43 -> 8.7758929 | F44: =F42-F43 -> 15.491772 | G44: =G42-G43 -> 22.686557 | H44: =H42-H43 -> 30.328805 | I44: =I42-I43 -> 37.781564 | J44: =J42-J43 -> 45.46814 | K44: =K42-K43 -> 53.242523
B45: Cash conversion (FCF before debt service / EBITDA) | E45: =E40/E20 -> 0.66203673 | F45: =F40/F20 -> 0.65776647 | G45: =G40/G20 -> 0.65391329 | H45: =H40/H20 -> 0.65035796 | I45: =I40/I20 -> 0.64640411 | J45: =J40/J20 -> 0.63912848 | K45: =K40/K20 -> 0.63452075

Sheet Debt
B1: Debt schedules, interest and credit statistics
B2: USD millions. Interest accrues on opening balances (no circular references). Cash waterfall: mandatory amortization, revolver, then the cash sweep.
B4: Projection year | D4: =COLUMN()-COLUMN($D$1) -> 0 | E4: =COLUMN()-COLUMN($D$1) -> 1 | F4: =COLUMN()-COLUMN($D$1) -> 2 | G4: =COLUMN()-COLUMN($D$1) -> 3 | H4: =COLUMN()-COLUMN($D$1) -> 4 | I4: =COLUMN()-COLUMN($D$1) -> 5 | J4: =COLUMN()-COLUMN($D$1) -> 6 | K4: =COLUMN()-COLUMN($D$1) -> 7
B5: Fiscal year | D5: =$D$9+D4 -> 2026 | E5: =$D$9+E4 -> 2027 | F5: =$D$9+F4 -> 2028 | G5: =$D$9+G4 -> 2029 | H5: =$D$9+H4 -> 2030 | I5: =$D$9+I4 -> 2031 | J5: =$D$9+J4 -> 2032 | K5: =$D$9+K4 -> 2033
B6: Chart label | D6: Close | E6: ="FY"&E5&"E" -> FY2027E | F6: ="FY"&F5&"E" -> FY2028E | G6: ="FY"&G5&"E" -> FY2029E | H6: ="FY"&H5&"E" -> FY2030E | I6: ="FY"&I5&"E" -> FY2031E | J6: ="FY"&J5&"E" -> FY2032E | K6: ="FY"&K5&"E" -> FY2033E
B8: Linked assumptions
B9: Closing fiscal year | D9: =Inputs!$D$13 -> 2026
B10: Revolver commitment | D10: =Inputs!$D$25 -> 60
B11: Revolver rate (base + spread) | D11: =Inputs!$D$29+Inputs!$D$30 -> 0.08
B12: Commitment fee on undrawn revolver | D12: =Inputs!$D$32 -> 0.005
B13: Term loan rate (base + spread) | D13: =Inputs!$D$29+Inputs!$D$31 -> 0.0875
B14: Sub notes rate (cash or PIK coupon) | D14: =IF(Inputs!$D$35=1,Inputs!$D$34,Inputs!$D$33) -> 0.11
B15: Sub notes PIK switch | D15: =Inputs!$D$35 -> 0
B16: Interest income rate | D16: =Inputs!$D$36 -> 0.02
B17: Cash sweep (% of excess cash flow) | D17: =Inputs!$D$37 -> 0.75
B18: Minimum cash | D18: =Inputs!$D$20 -> 20
B19: Original term loan | D19: =Transaction!$D$19 -> 400
B21: Cash waterfall
B22: Opening cash | E22: =D28 -> 20 | F22: =E28 -> 22.193973 | G22: =F28 -> 26.066916 | H22: =G28 -> 31.738555 | I22: =H28 -> 39.320757 | J22: =I28 -> 48.766148 | K22: =J28 -> 60.133182
B23: Free cash flow after debt service | E23: =Operating!E44 -> 8.7758929 | F23: =Operating!F44 -> 15.491772 | G23: =Operating!G44 -> 22.686557 | H23: =Operating!H44 -> 30.328805 | I23: =Operating!I44 -> 37.781564 | J23: =Operating!J44 -> 45.46814 | K23: =Operating!K44 -> 53.242523
B24: Cash before revolver and sweep | E24: =E22+E23 -> 28.775893 | F24: =F22+F23 -> 37.685745 | G24: =G22+G23 -> 48.753473 | H24: =H22+H23 -> 62.06736 | I24: =I22+I23 -> 77.10232 | J24: =J22+J23 -> 94.234287 | K24: =K22+K23 -> 113.37571
B25: Cash above minimum (before revolver) | E25: =E24-$D$18 -> 8.7758929 | F25: =F24-$D$18 -> 17.685745 | G25: =G24-$D$18 -> 28.753473 | H25: =H24-$D$18 -> 42.06736 | I25: =I24-$D$18 -> 57.10232 | J25: =J24-$D$18 -> 74.234287 | K25: =K24-$D$18 -> 93.375705
B26: Cash above minimum (after revolver) | E26: =E25+E32-E33 -> 8.7758929 | F26: =F25+F32-F33 -> 17.685745 | G26: =G25+G32-G33 -> 28.753473 | H26: =H25+H32-H33 -> 42.06736 | I26: =I25+I32-I33 -> 57.10232 | J26: =J25+J32-J33 -> 74.234287 | K26: =K25+K32-K33 -> 93.375705
B27: Excess cash flow subject to sweep | E27: =MAX(0,E23-E33) -> 8.7758929 | F27: =MAX(0,F23-F33) -> 15.491772 | G27: =MAX(0,G23-G33) -> 22.686557 | H27: =MAX(0,H23-H33) -> 30.328805 | I27: =MAX(0,I23-I33) -> 37.781564 | J27: =MAX(0,J23-J33) -> 45.46814 | K27: =MAX(0,K23-K33) -> 53.242523
B28: Closing cash | D28: =Transaction!$D$30 -> 20 | E28: =E24+E32-E33-E40 -> 22.193973 | F28: =F24+F32-F33-F40 -> 26.066916 | G28: =G24+G32-G33-G40 -> 31.738555 | H28: =H24+H32-H33-H40 -> 39.320757 | I28: =I24+I32-I33-I40 -> 48.766148 | J28: =J24+J32-J33-J40 -> 60.133182 | K28: =K24+K32-K33-K40 -> 73.443813
B30: Revolver
B31: Opening balance | E31: =D34 -> 0 | F31: =E34 -> 0 | G31: =F34 -> 0 | H31: =G34 -> 0 | I31: =H34 -> 0 | J31: =I34 -> 0 | K31: =J34 -> 0
B32: Draw | E32: =MIN(MAX(-E25,0),$D$10-E31) -> 0 | F32: =MIN(MAX(-F25,0),$D$10-F31) -> 0 | G32: =MIN(MAX(-G25,0),$D$10-G31) -> 0 | H32: =MIN(MAX(-H25,0),$D$10-H31) -> 0 | I32: =MIN(MAX(-I25,0),$D$10-I31) -> 0 | J32: =MIN(MAX(-J25,0),$D$10-J31) -> 0 | K32: =MIN(MAX(-K25,0),$D$10-K31) -> 0
B33: Repayment | E33: =MIN(E31,MAX(E25,0)) -> 0 | F33: =MIN(F31,MAX(F25,0)) -> 0 | G33: =MIN(G31,MAX(G25,0)) -> 0 | H33: =MIN(H31,MAX(H25,0)) -> 0 | I33: =MIN(I31,MAX(I25,0)) -> 0 | J33: =MIN(J31,MAX(J25,0)) -> 0 | K33: =MIN(K31,MAX(K25,0)) -> 0
B34: Closing balance | D34: =Transaction!$D$18 -> 0 | E34: =E31+E32-E33 -> 0 | F34: =F31+F32-F33 -> 0 | G34: =G31+G32-G33 -> 0 | H34: =H31+H32-H33 -> 0 | I34: =I31+I32-I33 -> 0 | J34: =J31+J32-J33 -> 0 | K34: =K31+K32-K33 -> 0
B36: Senior term loan
B37: Mandatory amortization (% of original) | E37: =Inputs!E39 -> 0.025 | F37: =Inputs!F39 -> 0.025 | G37: =Inputs!G39 -> 0.025 | H37: =Inputs!H39 -> 0.025 | I37: =Inputs!I39 -> 0.025 | J37: =Inputs!J39 -> 0.025 | K37: =Inputs!K39 -> 0.025
B38: Opening balance | E38: =D41 -> 400 | F38: =E41 -> 383.41808 | G38: =F41 -> 361.79925 | H38: =G41 -> 334.78433 | I38: =H41 -> 302.03773 | J38: =I41 -> 263.70156 | K38: =J41 -> 219.60045
B39: Mandatory amortization | E39: =MIN(E38,E37*$D$19) -> 10 | F39: =MIN(F38,F37*$D$19) -> 10 | G39: =MIN(G38,G37*$D$19) -> 10 | H39: =MIN(H38,H37*$D$19) -> 10 | I39: =MIN(I38,I37*$D$19) -> 10 | J39: =MIN(J38,J37*$D$19) -> 10 | K39: =MIN(K38,K37*$D$19) -> 10
B40: Cash sweep | E40: =MAX(0,MIN(E38-E39,$D$17*E27,E26)) -> 6.5819196 | F40: =MAX(0,MIN(F38-F39,$D$17*F27,F26)) -> 11.618829 | G40: =MAX(0,MIN(G38-G39,$D$17*G27,G26)) -> 17.014918 | H40: =MAX(0,MIN(H38-H39,$D$17*H27,H26)) -> 22.746603 | I40: =MAX(0,MIN(I38-I39,$D$17*I27,I26)) -> 28.336173 | J40: =MAX(0,MIN(J38-J39,$D$17*J27,J26)) -> 34.101105 | K40: =MAX(0,MIN(K38-K39,$D$17*K27,K26)) -> 39.931892
B41: Closing balance | D41: =Transaction!$D$19 -> 400 | E41: =E38-E39-E40 -> 383.41808 | F41: =F38-F39-F40 -> 361.79925 | G41: =G38-G39-G40 -> 334.78433 | H41: =H38-H39-H40 -> 302.03773 | I41: =I38-I39-I40 -> 263.70156 | J41: =J38-J39-J40 -> 219.60045 | K41: =K38-K39-K40 -> 169.66856
B43: Subordinated notes
B44: Opening balance | E44: =D46 -> 150 | F44: =E46 -> 150 | G44: =F46 -> 150 | H44: =G46 -> 150 | I44: =H46 -> 150 | J44: =I46 -> 150 | K44: =J46 -> 150
B45: PIK accrual | E45: =E54 -> 0 | F45: =F54 -> 0 | G45: =G54 -> 0 | H45: =H54 -> 0 | I45: =I54 -> 0 | J45: =J54 -> 0 | K45: =K54 -> 0
B46: Closing balance | D46: =Transaction!$D$20 -> 150 | E46: =E44+E45 -> 150 | F46: =F44+F45 -> 150 | G46: =G44+G45 -> 150 | H46: =H44+H45 -> 150 | I46: =I44+I45 -> 150 | J46: =J44+J45 -> 150 | K46: =K44+K45 -> 150
...

Sheet Returns
B1: Exit, returns and value creation bridge
B2: USD millions. Sponsor IRR is the closed form MOIC^(1/years) - 1, cross-checked against Excel's IRR() on the cash flow row.
B4: Linked inputs
B5: Exit year | D5: =Inputs!$D$47 -> 5
B6: Exit EV / EBITDA | D6: =Inputs!$D$48 -> 9
B7: Entry EV / EBITDA | D7: =Inputs!$D$16 -> 9
B8: LTM EBITDA at entry | D8: =Inputs!$D$15 -> 100
B9: Total entry equity (sponsor + rollover) | D9: =Transaction!$D$44 -> 403.25
B10: Sponsor equity invested | D10: =Transaction!$D$22 -> 378.25
B11: Option pool (% of equity gain) | D11: =Inputs!$D$22 -> 0.05
B12: Net debt at close | D12: =Transaction!$D$43 -> 530
B13: Transaction and financing fees | D13: =Transaction!$D$9+Transaction!$D$13 -> 33.25
B15: Exit valuation
B16: EBITDA in exit year | D16: =INDEX(Operating!$E$20:$K$20,D5) -> 139.57747
B17: Exit enterprise value | D17: =D16*D6 -> 1256.1972
B18: Less: revolver | D18: =INDEX(Debt!$E$34:$K$34,D5) -> 0
B19: Less: senior term loan | D19: =INDEX(Debt!$E$41:$K$41,D5) -> 263.70156
B20: Less: subordinated notes (incl. PIK) | D20: =INDEX(Debt!$E$46:$K$46,D5) -> 150
B21: Plus: cash | D21: =INDEX(Debt!$E$28:$K$28,D5) -> 48.766148
B22: Net debt at exit | D22: =D18+D19+D20-D21 -> 364.93541
B23: Exit equity value (100%) | D23: =D17-D22 -> 891.26181
B25: Distribution and sponsor returns
B26: Equity gain (exit equity less entry equity) | D26: =D23-D9 -> 488.01181
B27: Management option pool value | D27: =D11*MAX(0,D26) -> 24.400591
B28: Equity to investors (sponsor + rollover) | D28: =D23-D27 -> 866.86122
B29: Sponsor ownership of investor equity | D29: =D10/D9 -> 0.93800372
B30: Sponsor exit proceeds | D30: =D29*D28 -> 813.11905
B31: Rollover holder exit proceeds | D31: =D28-D30 -> 53.742171
B32: Sponsor MOIC | D32: =D30/D10 -> 2.1496869
B33: Sponsor IRR | D33: =IF(D32<=0,-1,D32^(1/D5)-1) -> 0.16540007
B35: Value creation bridge (equity gain, 100% of equity)
B36: Convention: EBITDA growth at the entry multiple; multiple expansion on exit EBITDA | D36: $mm | E36: % of gain | F36: x entry equity
B37: Entry equity (sponsor + rollover) | D37: =D9 -> 403.25
B38: EBITDA growth (x entry multiple) | D38: =D7*(D16-D8) -> 356.19722 | E38: =IF(ABS(D42)>0.000000001,D38/D42,0) -> 0.72989467 | F38: =D38/D37 -> 0.88331612
B39: Multiple expansion (x exit EBITDA) | D39: =(D6-D7)*D16 -> 0 | E39: =IF(ABS(D42)>0.000000001,D39/D42,0) -> 0 | F39: =D39/D37 -> 0
B40: Net debt paydown (net debt at close less at exit) | D40: =D12-D22 -> 165.06459 | E40: =IF(ABS(D42)>0.000000001,D40/D42,0) -> 0.33823892 | F40: =D40/D37 -> 0.40933562
B41: Transaction and financing costs | D41: =-D13 -> -33.25 | E41: =IF(ABS(D42)>0.000000001,D41/D42,0) -> -0.068133597 | F41: =D41/D37 -> -0.082455053
B42: Total equity gain | D42: =SUM(D38:D41) -> 488.01181 | E42: =IF(ABS(D42)>0.000000001,D42/D42,0) -> 1 | F42: =D42/D37 -> 1.2101967
B43: Exit equity value | D43: =D37+D42 -> 891.26181
B44: Check: bridge exit equity less valuation exit equity | D44: =D43-D23 -> 0
...

Sheet Sensitivity
B1: Sensitivity analysis (live formulas, no data tables)
B2: Entry multiple, exit multiple and exit year leave the debt schedule unchanged, so each grid cell is a closed-form formula on the model rows below.
B4: Linked inputs
B5: Exit year | D5: =Inputs!$D$47 -> 5
B6: Exit EV / EBITDA | D6: =Inputs!$D$48 -> 9
B7: Entry EV / EBITDA | D7: =Inputs!$D$16 -> 9
B8: Multiple step | D8: =Inputs!$D$49 -> 0.5
B9: LTM EBITDA | D9: =Inputs!$D$15 -> 100
B10: Transaction fees (% of EV) | D10: =Inputs!$D$17 -> 0.02
B11: Financing fees | D11: =Transaction!$D$13 -> 15.25
B12: Minimum cash | D12: =Inputs!$D$20 -> 20
B13: Total debt at close | D13: =Transaction!$D$41 -> 550
B14: Option pool (% of equity gain) | D14: =Inputs!$D$22 -> 0.05
B15: Total entry equity | D15: =Transaction!$D$44 -> 403.25
B17: Projection year | D17: =COLUMN()-COLUMN($D$1) -> 0 | E17: =COLUMN()-COLUMN($D$1) -> 1 | F17: =COLUMN()-COLUMN($D$1) -> 2 | G17: =COLUMN()-COLUMN($D$1) -> 3 | H17: =COLUMN()-COLUMN($D$1) -> 4 | I17: =COLUMN()-COLUMN($D$1) -> 5 | J17: =COLUMN()-COLUMN($D$1) -> 6 | K17: =COLUMN()-COLUMN($D$1) -> 7
B18: EBITDA by year | E18: =Operating!E20 -> 106 | F18: =Operating!F20 -> 114.62575 | G18: =Operating!G20 -> 123.29257 | H18: =Operating!H20 -> 131.90838 | I18: =Operating!I20 -> 139.57747 | J18: =Operating!J20 -> 147.64903 | K18: =Operating!K20 -> 154.53379
B19: Net debt by year | E19: =Debt!E64 -> 511.22411 | F19: =Debt!F64 -> 485.73233 | G19: =Debt!G64 -> 453.04578 | H19: =Debt!H64 -> 412.71697 | I19: =Debt!I64 -> 364.93541 | J19: =Debt!J64 -> 309.46727 | K19: =Debt!K64 -> 246.22475
B21: Grid 1: entry multiple (rows) vs exit multiple (columns), exit year per Inputs
B22: Sponsor MOIC | C22: Entry \ Exit | D22: =$D$6+(-2)*$D$8 -> 8 | E22: =$D$6+(-1)*$D$8 -> 8.5 | F22: =$D$6+(0)*$D$8 -> 9 | G22: =$D$6+(1)*$D$8 -> 9.5 | H22: =$D$6+(2)*$D$8 -> 10 | I22: Entry equity
B23: Exit equity at that exit multiple (100%) | D23: =D22*INDEX($E$18:$K$18,$D$5)-INDEX($E$19:$K$19,$D$5) -> 751.68434 | E23: =E22*INDEX($E$18:$K$18,$D$5)-INDEX($E$19:$K$19,$D$5) -> 821.47308 | F23: =F22*INDEX($E$18:$K$18,$D$5)-INDEX($E$19:$K$19,$D$5) -> 891.26181 | G23: =G22*INDEX($E$18:$K$18,$D$5)-INDEX($E$19:$K$19,$D$5) -> 961.05055 | H23: =H22*INDEX($E$18:$K$18,$D$5)-INDEX($E$19:$K$19,$D$5) -> 1030.8393
C24: =$D$7+(-2)*$D$8 -> 8 | D24: =(D$23-$D$14*MAX(0,D$23-$I24))/$I24 -> 2.4204569 | E24: =(E$23-$D$14*MAX(0,E$23-$I24))/$I24 -> 2.6405375 | F24: =(F$23-$D$14*MAX(0,F$23-$I24))/$I24 -> 2.8606182 | G24: =(G$23-$D$14*MAX(0,G$23-$I24))/$I24 -> 3.0806988 | H24: =(H$23-$D$14*MAX(0,H$23-$I24))/$I24 -> 3.3007795 | I24: =C24*$D$9*(1+$D$10)+$D$11+$D$12-$D$13 -> 301.25
C25: =$D$7+(-1)*$D$8 -> 8.5 | D25: =(D$23-$D$14*MAX(0,D$23-$I25))/$I25 -> 2.0772537 | E25: =(E$23-$D$14*MAX(0,E$23-$I25))/$I25 -> 2.2654703 | F25: =(F$23-$D$14*MAX(0,F$23-$I25))/$I25 -> 2.4536869 | G25: =(G$23-$D$14*MAX(0,G$23-$I25))/$I25 -> 2.6419035 | H25: =(H$23-$D$14*MAX(0,H$23-$I25))/$I25 -> 2.8301201 | I25: =C25*$D$9*(1+$D$10)+$D$11+$D$12-$D$13 -> 352.25
C26: =$D$7+(0)*$D$8 -> 9 | D26: =(D$23-$D$14*MAX(0,D$23-$I26))/$I26 -> 1.8208621 | E26: =(E$23-$D$14*MAX(0,E$23-$I26))/$I26 -> 1.9852745 | F26: =(F$23-$D$14*MAX(0,F$23-$I26))/$I26 -> 2.1496869 | G26: =(G$23-$D$14*MAX(0,G$23-$I26))/$I26 -> 2.3140992 | H26: =(H$23-$D$14*MAX(0,H$23-$I26))/$I26 -> 2.4785116 | I26: =C26*$D$9*(1+$D$10)+$D$11+$D$12-$D$13 -> 403.25
C27: =$D$7+(1)*$D$8 -> 9.5 | D27: =(D$23-$D$14*MAX(0,D$23-$I27))/$I27 -> 1.6220421 | E27: =(E$23-$D$14*MAX(0,E$23-$I27))/$I27 -> 1.7679954 | F27: =(F$23-$D$14*MAX(0,F$23-$I27))/$I27 -> 1.9139488 | G27: =(G$23-$D$14*MAX(0,G$23-$I27))/$I27 -> 2.0599021 | H27: =(H$23-$D$14*MAX(0,H$23-$I27))/$I27 -> 2.2058554 | I27: =C27*$D$9*(1+$D$10)+$D$11+$D$12-$D$13 -> 454.25
C28: =$D$7+(2)*$D$8 -> 10 | D28: =(D$23-$D$14*MAX(0,D$23-$I28))/$I28 -> 1.46336 | E28: =(E$23-$D$14*MAX(0,E$23-$I28))/$I28 -> 1.5945808 | F28: =(F$23-$D$14*MAX(0,F$23-$I28))/$I28 -> 1.7258015 | G28: =(G$23-$D$14*MAX(0,G$23-$I28))/$I28 -> 1.8570223 | H28: =(H$23-$D$14*MAX(0,H$23-$I28))/$I28 -> 1.9882431 | I28: =C28*$D$9*(1+$D$10)+$D$11+$D$12-$D$13 -> 505.25
B32: Grid 1: sponsor IRR
B33: Sponsor IRR | C33: Entry \ Exit | D33: =D22 -> 8 | E33: =E22 -> 8.5 | F33: =F22 -> 9 | G33: =G22 -> 9.5 | H33: =H22 -> 10
C34: =C24 -> 8 | D34: =IF(D24<=0,-1,D24^(1/$D$5)-1) -> 0.19338196 | E34: =IF(E24<=0,-1,E24^(1/$D$5)-1) -> 0.21433488 | F34: =IF(F24<=0,-1,F24^(1/$D$5)-1) -> 0.23393413 | G34: =IF(G24<=0,-1,G24^(1/$D$5)-1) -> 0.25236191 | H34: =IF(H24<=0,-1,H24^(1/$D$5)-1) -> 0.26976485
C35: =C25 -> 8.5 | D35: =IF(D25<=0,-1,D25^(1/$D$5)-1) -> 0.15743846 | E35: =IF(E25<=0,-1,E25^(1/$D$5)-1) -> 0.17769187 | F35: =IF(F25<=0,-1,F25^(1/$D$5)-1) -> 0.19664087 | G35: =IF(G25<=0,-1,G25^(1/$D$5)-1) -> 0.21446049 | H35: =IF(H25<=0,-1,H25^(1/$D$5)-1) -> 0.23129176
C36: =C26 -> 9 | D36: =IF(D26<=0,-1,D26^(1/$D$5)-1) -> 0.12734128 | E36: =IF(E26<=0,-1,E26^(1/$D$5)-1) -> 0.14700183 | F36: =IF(F26<=0,-1,F26^(1/$D$5)-1) -> 0.16540007 | G36: =IF(G26<=0,-1,G26^(1/$D$5)-1) -> 0.1827049 | H36: =IF(H26<=0,-1,H26^(1/$D$5)-1) -> 0.19905248
C37: =C27 -> 9.5 | D37: =IF(D27<=0,-1,D27^(1/$D$5)-1) -> 0.10157082 | E37: =IF(E27<=0,-1,E27^(1/$D$5)-1) -> 0.12071769 | F37: =IF(F27<=0,-1,F27^(1/$D$5)-1) -> 0.13863902 | G37: =IF(G27<=0,-1,G27^(1/$D$5)-1) -> 0.15549831 | H37: =IF(H27<=0,-1,H27^(1/$D$5)-1) -> 0.17142748
C38: =C28 -> 10 | D38: =IF(D28<=0,-1,D28^(1/$D$5)-1) -> 0.079121224 | E38: =IF(E28<=0,-1,E28^(1/$D$5)-1) -> 0.097815362 | F38: =IF(F28<=0,-1,F28^(1/$D$5)-1) -> 0.11531661 | G38: =IF(G28<=0,-1,G28^(1/$D$5)-1) -> 0.13178367 | H38: =IF(H28<=0,-1,H28^(1/$D$5)-1) -> 0.14734465
B44: Grid 2: exit multiple (rows) vs exit year (columns), entry multiple per Inputs
B45: Sponsor MOIC | C45: Exit x \ Year | D45: 3 | E45: 4 | F45: 5 | G45: 6 | H45: 7
C46: =$D$6+(-2)*$D$8 -> 8 | D46: =(($C46*INDEX($E$18:$K$18,D$45)-INDEX($E$19:$K$19,D$45))-$D$14*MAX(0,($C46*INDEX($E$18:$K$18,D$45)-INDEX($E$19:$K$19,D$45))-$D$15))/$D$15 -> 1.3063672 | E46: =(($C46*INDEX($E$18:$K$18,E$45)-INDEX($E$19:$K$19,E$45))-$D$14*MAX(0,($C46*INDEX($E$18:$K$18,E$45)-INDEX($E$19:$K$19,E$45))-$D$15))/$D$15 -> 1.5637571 | F46: =(($C46*INDEX($E$18:$K$18,F$45)-INDEX($E$19:$K$19,F$45))-$D$14*MAX(0,($C46*INDEX($E$18:$K$18,F$45)-INDEX($E$19:$K$19,F$45))-$D$15))/$D$15 -> 1.8208621 | G46: =(($C46*INDEX($E$18:$K$18,G$45)-INDEX($E$19:$K$19,G$45))-$D$14*MAX(0,($C46*INDEX($E$18:$K$18,G$45)-INDEX($E$19:$K$19,G$45))-$D$15))/$D$15 -> 2.1036609 | H46: =(($C46*INDEX($E$18:$K$18,H$45)-INDEX($E$19:$K$19,H$45))-$D$14*MAX(0,($C46*INDEX($E$18:$K$18,H$45)-INDEX($E$19:$K$19,H$45))-$D$15))/$D$15 -> 2.3824075
C47: =$D$6+(-1)*$D$8 -> 8.5 | D47: =(($C47*INDEX($E$18:$K$18,D$45)-INDEX($E$19:$K$19,D$45))-$D$14*MAX(0,($C47*INDEX($E$18:$K$18,D$45)-INDEX($E$19:$K$19,D$45))-$D$15))/$D$15 -> 1.4515972 | E47: =(($C47*INDEX($E$18:$K$18,E$45)-INDEX($E$19:$K$19,E$45))-$D$14*MAX(0,($C47*INDEX($E$18:$K$18,E$45)-INDEX($E$19:$K$19,E$45))-$D$15))/$D$15 -> 1.7191358 | F47: =(($C47*INDEX($E$18:$K$18,F$45)-INDEX($E$19:$K$19,F$45))-$D$14*MAX(0,($C47*INDEX($E$18:$K$18,F$45)-INDEX($E$19:$K$19,F$45))-$D$15))/$D$15 -> 1.9852745 | G47: =(($C47*INDEX($E$18:$K$18,G$45)-INDEX($E$19:$K$19,G$45))-$D$14*MAX(0,($C47*INDEX($E$18:$K$18,G$45)-INDEX($E$19:$K$19,G$45))-$D$15))/$D$15 -> 2.277581 | H47: =(($C47*INDEX($E$18:$K$18,H$45)-INDEX($E$19:$K$19,H$45))-$D$14*MAX(0,($C47*INDEX($E$18:$K$18,H$45)-INDEX($E$19:$K$19,H$45))-$D$15))/$D$15 -> 2.5644374
C48: =$D$6+(0)*$D$8 -> 9 | D48: =(($C48*INDEX($E$18:$K$18,D$45)-INDEX($E$19:$K$19,D$45))-$D$14*MAX(0,($C48*INDEX($E$18:$K$18,D$45)-INDEX($E$19:$K$19,D$45))-$D$15))/$D$15 -> 1.5968271 | E48: =(($C48*INDEX($E$18:$K$18,E$45)-INDEX($E$19:$K$19,E$45))-$D$14*MAX(0,($C48*INDEX($E$18:$K$18,E$45)-INDEX($E$19:$K$19,E$45))-$D$15))/$D$15 -> 1.8745146 | F48: =(($C48*INDEX($E$18:$K$18,F$45)-INDEX($E$19:$K$19,F$45))-$D$14*MAX(0,($C48*INDEX($E$18:$K$18,F$45)-INDEX($E$19:$K$19,F$45))-$D$15))/$D$15 -> 2.1496869 | G48: =(($C48*INDEX($E$18:$K$18,G$45)-INDEX($E$19:$K$19,G$45))-$D$14*MAX(0,($C48*INDEX($E$18:$K$18,G$45)-INDEX($E$19:$K$19,G$45))-$D$15))/$D$15 -> 2.4515012 | H48: =(($C48*INDEX($E$18:$K$18,H$45)-INDEX($E$19:$K$19,H$45))-$D$14*MAX(0,($C48*INDEX($E$18:$K$18,H$45)-INDEX($E$19:$K$19,H$45))-$D$15))/$D$15 -> 2.7464673
C49: =$D$6+(1)*$D$8 -> 9.5 | D49: =(($C49*INDEX($E$18:$K$18,D$45)-INDEX($E$19:$K$19,D$45))-$D$14*MAX(0,($C49*INDEX($E$18:$K$18,D$45)-INDEX($E$19:$K$19,D$45))-$D$15))/$D$15 -> 1.742057 | E49: =(($C49*INDEX($E$18:$K$18,E$45)-INDEX($E$19:$K$19,E$45))-$D$14*MAX(0,($C49*INDEX($E$18:$K$18,E$45)-INDEX($E$19:$K$19,E$45))-$D$15))/$D$15 -> 2.0298933 | F49: =(($C49*INDEX($E$18:$K$18,F$45)-INDEX($E$19:$K$19,F$45))-$D$14*MAX(0,($C49*INDEX($E$18:$K$18,F$45)-INDEX($E$19:$K$19,F$45))-$D$15))/$D$15 -> 2.3140992 | G49: =(($C49*INDEX($E$18:$K$18,G$45)-INDEX($E$19:$K$19,G$45))-$D$14*MAX(0,($C49*INDEX($E$18:$K$18,G$45)-INDEX($E$19:$K$19,G$45))-$D$15))/$D$15 -> 2.6254213 | H49: =(($C49*INDEX($E$18:$K$18,H$45)-INDEX($E$19:$K$19,H$45))-$D$14*MAX(0,($C49*INDEX($E$18:$K$18,H$45)-INDEX($E$19:$K$19,H$45))-$D$15))/$D$15 -> 2.9284971
C50: =$D$6+(2)*$D$8 -> 10 | D50: =(($C50*INDEX($E$18:$K$18,D$45)-INDEX($E$19:$K$19,D$45))-$D$14*MAX(0,($C50*INDEX($E$18:$K$18,D$45)-INDEX($E$19:$K$19,D$45))-$D$15))/$D$15 -> 1.887287 | E50: =(($C50*INDEX($E$18:$K$18,E$45)-INDEX($E$19:$K$19,E$45))-$D$14*MAX(0,($C50*INDEX($E$18:$K$18,E$45)-INDEX($E$19:$K$19,E$45))-$D$15))/$D$15 -> 2.1852721 | F50: =(($C50*INDEX($E$18:$K$18,F$45)-INDEX($E$19:$K$19,F$45))-$D$14*MAX(0,($C50*INDEX($E$18:$K$18,F$45)-INDEX($E$19:$K$19,F$45))-$D$15))/$D$15 -> 2.4785116 | G50: =(($C50*INDEX($E$18:$K$18,G$45)-INDEX($E$19:$K$19,G$45))-$D$14*MAX(0,($C50*INDEX($E$18:$K$18,G$45)-INDEX($E$19:$K$19,G$45))-$D$15))/$D$15 -> 2.7993414 | H50: =(($C50*INDEX($E$18:$K$18,H$45)-INDEX($E$19:$K$19,H$45))-$D$14*MAX(0,($C50*INDEX($E$18:$K$18,H$45)-INDEX($E$19:$K$19,H$45))-$D$15))/$D$15 -> 3.110527
B52: Grid 2: sponsor IRR
...

Sheet Checks
B1: Model integrity checks
B2: Each check reports a violation size; it passes when the size is within tolerance.
B4: Check | D4: Violation | E4: Tolerance | F4: Status
B5: Sources equal uses | D5: =ABS(Transaction!$D$33) -> 0 | E5: 1e-06 | F5: =IF(ISNUMBER(D5),IF(D5<=E5,"OK","ERROR"),"ERROR") -> OK
B6: Debt plus equity equals total uses | D6: =ABS(Transaction!$D$45-Transaction!$D$31) -> 0 | E6: 1e-06 | F6: =IF(ISNUMBER(D6),IF(D6<=E6,"OK","ERROR"),"ERROR") -> OK
B7: Debt balances never negative (revolver, term loan, notes) | D7: =MAX(0,-MIN(Debt!$D$34:$K$34,Debt!$D$41:$K$41,Debt!$D$46:$K$46)) -> 0 | E7: 1e-06 | F7: =IF(ISNUMBER(D7),IF(D7<=E7,"OK","ERROR"),"ERROR") -> OK
B8: Cash never below minimum | D8: =MAX(0,Debt!$D$18-MIN(Debt!$D$28:$K$28)) -> 0 | E8: 1e-06 | F8: =IF(ISNUMBER(D8),IF(D8<=E8,"OK","ERROR"),"ERROR") -> OK
B9: Revolver never above commitment | D9: =MAX(0,MAX(Debt!$D$34:$K$34)-Debt!$D$10) -> 0 | E9: 1e-06 | F9: =IF(ISNUMBER(D9),IF(D9<=E9,"OK","ERROR"),"ERROR") -> OK
B10: Revolver roll-forward (closing = opening + draws - repayments) | D10: =ABS(Debt!$K$34-(Debt!$D$34+SUM(Debt!$E$32:$K$32)-SUM(Debt!$E$33:$K$33))) -> 0 | E10: 1e-06 | F10: =IF(ISNUMBER(D10),IF(D10<=E10,"OK","ERROR"),"ERROR") -> OK
B11: Term loan roll-forward (closing = opening - amortization - sweep) | D11: =ABS(Debt!$K$41-(Debt!$D$41-SUM(Debt!$E$39:$K$39)-SUM(Debt!$E$40:$K$40))) -> 0 | E11: 1e-06 | F11: =IF(ISNUMBER(D11),IF(D11<=E11,"OK","ERROR"),"ERROR") -> OK
B12: Sub notes roll-forward (closing = opening + PIK) | D12: =ABS(Debt!$K$46-(Debt!$D$46+SUM(Debt!$E$45:$K$45))) -> 0 | E12: 1e-06 | F12: =IF(ISNUMBER(D12),IF(D12<=E12,"OK","ERROR"),"ERROR") -> OK
B13: Cash roll-forward (free cash flow, revolver, sweep) | D13: =ABS(Debt!$K$28-(Debt!$D$28+SUM(Debt!$E$23:$K$23)+SUM(Debt!$E$32:$K$32)-SUM(Debt!$E$33:$K$33)-SUM(Debt!$E$40:$K$40))) -> 0 | E13: 1e-06 | F13: =IF(ISNUMBER(D13),IF(D13<=E13,"OK","ERROR"),"ERROR") -> OK
B14: Net debt roll-forward (opening - FCF after interest + PIK) | D14: =ABS(Debt!$K$64-(Debt!$D$64-SUM(Operating!$E$42:$K$42)+SUM(Debt!$E$54:$K$54))) -> 0 | E14: 1e-06 | F14: =IF(ISNUMBER(D14),IF(D14<=E14,"OK","ERROR"),"ERROR") -> OK
B15: Value creation bridge sums to equity gain | D15: =ABS(Returns!$D$44) -> 0 | E15: 1e-06 | F15: =IF(ISNUMBER(D15),IF(D15<=E15,"OK","ERROR"),"ERROR") -> OK
B16: Sponsor bridge reconciles to proceeds less equity | D16: =ABS(Returns!$D$49) -> 0 | E16: 1e-06 | F16: =IF(ISNUMBER(D16),IF(D16<=E16,"OK","ERROR"),"ERROR") -> OK
B17: Closed-form IRR equals Excel IRR() | D17: =ABS(Returns!$D$33-Returns!$D$54) -> 0 | E17: 1e-06 | F17: =IF(ISNUMBER(D17),IF(D17<=E17,"OK","ERROR"),"ERROR") -> OK
B18: Grid 1 centre MOIC equals model MOIC | D18: =ABS(Sensitivity!$F$26-Returns!$D$32) -> 0 | E18: 1e-06 | F18: =IF(ISNUMBER(D18),IF(D18<=E18,"OK","ERROR"),"ERROR") -> OK
B19: Grid 1 centre IRR equals model IRR | D19: =ABS(Sensitivity!$F$36-Returns!$D$33) -> 0 | E19: 1e-06 | F19: =IF(ISNUMBER(D19),IF(D19<=E19,"OK","ERROR"),"ERROR") -> OK
B20: Grid 2 centre MOIC equals model MOIC | D20: =ABS(INDEX(Sensitivity!$D$48:$H$48,MATCH(Inputs!$D$47,Sensitivity!$D$45:$H$45,0))-Returns!$D$32) -> 0 | E20: 1e-06 | F20: =IF(ISNUMBER(D20),IF(D20<=E20,"OK","ERROR"),"ERROR") -> OK
B21: Grid 2 centre IRR equals model IRR | D21: =ABS(INDEX(Sensitivity!$D$56:$H$56,MATCH(Inputs!$D$47,Sensitivity!$D$53:$H$53,0))-Returns!$D$33) -> 0 | E21: 1e-06 | F21: =IF(ISNUMBER(D21),IF(D21<=E21,"OK","ERROR"),"ERROR") -> OK
B22: Exit year is an integer between 3 and 7 | D22: =IF(AND(Inputs!$D$47>=3,Inputs!$D$47<=7,Inputs!$D$47=INT(Inputs!$D$47)),0,1) -> 0 | E22: 1e-06 | F22: =IF(ISNUMBER(D22),IF(D22<=E22,"OK","ERROR"),"ERROR") -> OK
B23: Revolver drawn at close within commitment | D23: =MAX(0,Inputs!$D$26-Inputs!$D$25) -> 0 | E23: 1e-06 | F23: =IF(ISNUMBER(D23),IF(D23<=E23,"OK","ERROR"),"ERROR") -> OK
B24: Cash taxes never negative | D24: =MAX(0,-MIN(Operating!$E$32:$K$32)) -> 0 | E24: 1e-06 | F24: =IF(ISNUMBER(D24),IF(D24<=E24,"OK","ERROR"),"ERROR") -> OK
B26: Overall model status | D26: =COUNTIF(F5:F24,"ERROR") -> 0 | E26: errors | F26: =IF(D26=0,"ALL CHECKS PASS","CHECK FAILURES") -> ALL CHECKS PASS
